package ro.ase.cts.seminar14.unittesting;

import static org.junit.Assert.assertEquals;
import static org.junit.Assert.fail;

import org.junit.After;
import org.junit.Before;
import org.junit.Test;

class StudentTestCase {
	
	static Student student;
	static String defaultName = "anonim";
	static int defaultVarsta = 18;
	static int defaultNote[];
	static int NR_NOTE_DEFAULT = 3;
	
	@Before
	static void setUpBeforeClass() throws Exception {
		System.out.println("beforeClass was called...");
		defaultNote = new int[NR_NOTE_DEFAULT];
		defaultNote[0] = 8;
		defaultNote[1] = 9;
		defaultNote[2] = 10;
	}

	@After
	static void tearDownAfterClass() throws Exception {
		System.out.println("tearDownClass was called...");
	}

	@Before
	void setUp() throws Exception {
		System.out.println("setUp was called...");
		student = new Student(defaultName, defaultVarsta, defaultNote);
	}

	@After
	void tearDown() throws Exception {
		System.out.println("teadDown was called...");
	}
	
	@Test
	void testCalculMedieOrdnance() {
		//here the order is irellevant
		int note[] = {10, 9, 8, 7, 6};
		try {
			student.setNote(note);
			float medie = student.computeAverage();
			float expectedMedie = 8;
			assertEquals(expectedMedie, medie, "Average does not compute correctly");
		} catch (StudentExceptionWrongValue e) {
			fail("Exception generated by setNote/computeAverage method");
		}
	}
	
	@Test
	void testCalculMedieCardinalityOne() {
		int note[] = new int[1];
		try {
			student.setNote(note);
		} catch (StudentExceptionWrongValue e) {
			fail("Exception generated by setNote method");
		}
		
		assertThrows(StudentExceptionWrongValue.class, () -> {
				student.computeAverage();
		});
	}

}

